Workbook

Sheet Sheet1
A1: Aktenzeichen | B1: Landgericht | C1: Verfügbar | D1: Die Beklagte wird verurteilt zu unterlassen | E1: Entscheidung (Untrelassung) | F1: Kather Augenstein | G1: Link DE | H1: Link EN | I1: Darts-IP | J1: eJustiz | K1: Link | L1: Zugehörigen Aktenzeichen | M1: Klage auf Unterlassung | N1: Urteil | O1: Prehuawei | P1: AASI | Q1: Streitwert | S1: First contact | T1: Date of complaint | U1: First notice of infringement (first contact?) | V1: First licensing offer | W1: Date of decision | X1: Dominant position | Y1: Abuse of dominant position | Z1: Notice of Infringement | AA1: Willingness to license | AB1: FRAND offer | AC1: Formal | AD1: Substantially | AE1: Pool | AF1: Worldwide
A2: 4a O 144/14 | B2: Duesseldorf | C2: Yes | D2: Yes | E2: Yes | F2: No | G2: - | H2: - | I2: Yes | J2: Yes | K2: http://www.justiz.nrw.de/nrwe/lgs/duesseldorf/lg_duesseldorf/j2015/4a_O_144_14_Urteil_20151103.html | L2: I-15 U 41/17 | M2: 08.09.2014 | N2: 03.11.2015 | O2: 1 | Q2: 500000 | S2: 20.12.2012 | T2: 18.12.2014 | U2: 18.12.2014 | V2: 13.10.2014 | W2: 03.11.2015 | AA2: Yes | AE2: Yes? | AF2: Yes
A3: 4b O 51/14 | B3: Duesseldorf | C3: Yes | D3: No | E3: No | F3: No | G3: - | H3: - | I3: Yes | J3: Yes | K3: http://www.justiz.nrw.de/nrwe/lgs/duesseldorf/lg_duesseldorf/j2016/4b_O_51_14_Schlussurteil_20160119.html | L3: - | M3: 10.03.2014 | N3: 19.01.2016 | O3: 1 | Q3: 2000000 | T3: 12.05.2014 | U3: 12.05.2014 | W3: 19.01.2016 | AA3: Yes | AE3: ? | AF3: ?
A4: 4a O 126/14 | B4: Duesseldorf | C4: Yes | D4: Yes | E4: Yes | F4: No | G4: - | H4: - | I4: Yes | J4: Yes | K4: http://www.justiz.nrw.de/nrwe/lgs/duesseldorf/lg_duesseldorf/j2016/4a_O_126_14_Teil_Verzichts_und_Schlussurteil_20160331.html | L4: 4a O 73/14; I-15 U 35/16 | M4: 23.07.2014 | N4: 31.03.2016 | O4: 1 | Q4: 2000000 | T4: 12.11.2014 | U4: 12.11.2014 | W4: 31.03.2016 | AB4: No? | AD4: No? | AE4: Yes | AF4: No?
A5: 4a O 73/14 | B5: Duesseldorf | C5: Yes | D5: Yes | E5: Yes | F5: Yes | G5: https://www.katheraugenstein.com/app/uploads/2016-03-31-4a-O-73_14-DE-pdf-2.pdf | H5: https://www.katheraugenstein.com/app/uploads/2016-03-31-4a-O-73_14-EN-pdf-1.pdf | I5: Yes | J5: Yes | K5: http://www.justiz.nrw.de/nrwe/lgs/duesseldorf/lg_duesseldorf/j2016/4a_O_73_14_Teil_Verzichts_und_Schlussurteil_20160331.html | L5: - | M5: 23.07.2014 | N5: 31.03.2016 | O5: 1 | Q5: 2000000 | T5: 23.07.2014 | U5: 23.07.2014 | W5: 31.03.2016
A6: 4a O 16/16 | B6: Duesseldorf | C6: Yes | D6: Yes | E6: No | F6: Yes | G6: https://www.katheraugenstein.com/app/uploads/2017-07-13-4a-O-16_16-DE-pdf-2.pdf | H6: https://www.katheraugenstein.com/app/uploads/2017-07-13-4a-O-16_16-EN-pdf-1.pdf | I6: Yes | J6: Yes | K6: http://www.justiz.nrw.de/nrwe/lgs/duesseldorf/lg_duesseldorf/j2017/4a_O_16_16_Urteil_20170713.html | L6: - | M6: 15.11.2016 | N6: 13.07.2017 | Q6: 1000000 | T6: 18.02.2016 | U6: 18.02.2016 | W6: 13.07.2017 | X6: Yes | Y6: Yes? | Z6: Yes | AA6: Yes | AE6: ? | AF6: Yes
A7: 4a O 35/16 | B7: Duesseldorf | C7: Yes | D7: Yes | E7: No | F7: No | G7: - | H7: - | I7: Yes | J7: Yes | K7: http://www.justiz.nrw.de/nrwe/lgs/duesseldorf/lg_duesseldorf/j2017/4a_O_35_16_Urteil_20170713.html | L7: - | M7: 15.11.2016 | N7: 13.07.2017 | Q7: 1000000 | T7: 09.04.2016 | U7: 09.04.2016 | W7: 13.07.2017 | X7: Yes | Z7: Yes | AA7: Yes
A8: 4c O 72/17 | B8: Duesseldorf | C8: Yes | D8: Yes | E8: No | F8: No | G8: - | H8: - | I8: Yes | J8: Yes | K8: http://www.justiz.nrw.de/nrwe/lgs/duesseldorf/lg_duesseldorf/j2018/4c_O_72_17_Urteil_20180711.html | L8: - | M8: 15.09.2017 | N8: 11.07.2018 | Q8: 4000000 | T8: 25.08.2017 | U8: 25.08.2017 | W8: 11.07.2018 | X8: Yes | Z8: Yes | AA8: Yes
A9: 4c O 77/17 | B9: Duesseldorf | C9: Yes | D9: Yes | E9: No | F9: No | G9: - | H9: - | I9: Yes | J9: Yes | K9: http://www.justiz.nrw.de/nrwe/lgs/duesseldorf/lg_duesseldorf/j2018/4c_O_77_17_Urteil_20180711.html | L9: - | M9: 31.01.2017 | N9: 11.07.2018 | Q9: 4000000 | T9: 11.09.2017 | U9: 11.09.2017 | W9: 11.07.2018 | X9: Yes | Z9: Yes | AA9: Yes
A10: 4a O 15/17 | B10: Duesseldorf | C10: Yes | D10: Yes | E10: Yes | F10: Yes | G10: https://www.katheraugenstein.com/app/uploads/2018-11-09-4a-O-15_17-DE-pdf.pdf | H10: https://www.katheraugenstein.com/app/uploads/2018-11-09-4a-O-15_17-EN-pdf.pdf | I10: Yes | J10: Yes | K10: http://www.justiz.nrw.de/nrwe/lgs/duesseldorf/lg_duesseldorf/j2018/4a_O_15_17_Urteil_20181109.html | L10: - | M10: 15.03.2017 | N10: 09.11.2018 | Q10: 2500000 | T10: 05.02.2017 | U10: 05.02.2017 | W10: 09.11.2018 | X10: Yes | Z10: Yes | AA10: Yes
A11: 4c O 3/17 | B11: Duesseldorf | C11: Yes | D11: Yes | E11: Yes | F11: No | G11: - | H11: - | I11: Yes | J11: Yes | K11: http://www.justiz.nrw.de/nrwe/lgs/duesseldorf/lg_duesseldorf/j2018/4c_O_3_17_Urteil_20181221.html | L11: - | M11: 01.04.2017 | N11: 21.12.2018 | Q11: 5000000/30000000 | T11: 11.01.2017 | U11: 11.01.2017 | W11: 21.12.2018
A12: 4a O 17/17 | B12: Duesseldorf | C12: Yes | D12: Yes | E12: Yes | F12: Yes | G12: https://www.katheraugenstein.com/app/uploads/2018-11-09-4a-O-17_17-DE-pdf.pdf | H12: https://www.katheraugenstein.com/app/uploads/2018-11-09-4a-O-17_17-EN-pdf.pdf | I12: Yes | J12: Yes | K12: http://www.justiz.nrw.de/nrwe/lgs/duesseldorf/lg_duesseldorf/j2018/4a_O_17_17_Urteil_20181109.html | L12: - | M12: 01.06.2017 | N12: 09.11.2018 | Q12: 5000000 | T12: 10.02.2017 | U12: 10.02.2017 | W12: 09.11.2018
A13: 4c O 81/17 | B13: Duesseldorf | C13: Yes | D13: Yes | E13: No | F13: Yes | G13: https://www.katheraugenstein.com:443/app/uploads/2018-07-11-4c-O-81_17-DE-pdf-2.pdf | H13: https://www.katheraugenstein.com:443/app/uploads/2018-07-11-4c-O-81_17-EN-pdf-2.pdf | I13: Yes | J13: Yes | K13: http://www.justiz.nrw.de/nrwe/lgs/duesseldorf/lg_duesseldorf/j2018/4c_O_81_17_Urteil_20180711.html | L13: - | M13: 15.06.2016 | N13: 11.07.2018 | Q13: 4000000 | T13: 24.09.2017 | U13: 24.09.2017 | W13: 11.07.2018
A14: 4c O 12/17 | B14: Duesseldorf | C14: Yes | D14: Yes? | E14: Yes? | F14: No | G14: - | H14: - | I14: Yes | J14: Yes | K14: http://www.justiz.nrw.de/nrwe/lgs/duesseldorf/lg_duesseldorf/j2019/4c_O_12_17_Urteil_20190108.html | L14: - | M14: 01.04.2017 | N14: 08.01.2019 | Q14: 30000000/10000000 | T14: 10.02.2017 | U14: 10.02.2017 | W14: 08.01.2019
A15: 4c O 44/18 | B15: Duesseldorf | C15: Yes | D15: Yes | E15: Yes | F15: No | G15: - | H15: - | I15: Yes | J15: Yes | K15: http://www.justiz.nrw.de/nrwe/lgs/duesseldorf/lg_duesseldorf/j2020/4c_O_44_18_Urteil_20200507.html | L15: - | M15: 01.10.2018 | N15: 07.05.2020 | Q15: 1000000 | W15: 07.05.2020
A16: 4c O 56/18 | B16: Duesseldorf | C16: Yes | D16: Yes | E16: Yes | F16: No | G16: - | H16: - | I16: Yes | J16: Yes | K16: http://www.justiz.nrw.de/nrwe/lgs/duesseldorf/lg_duesseldorf/j2020/4c_O_56_18_Urteil_20200507.html | L16: - | M16: 01.10.2018 | N16: 07.05.2020 | Q16: 1000000 | T16: 24.09.2018 | U16: 03.09.2018 | W16: 07.05.2020
A17: 4c O 69/18 | B17: Duesseldorf | C17: Yes | D17: Yes | E17: Yes | F17: No | G17: - | H17: - | I17: Yes | J17: Yes | K17: http://www.justiz.nrw.de/nrwe/lgs/duesseldorf/lg_duesseldorf/j2020/4c_O_69_18_Anerkenntnisurteil_20200507.html | L17: - | M17: 01.12.2018 | N17: 07.05.2020 | Q17: 1000000 | T17: 22.11.2018 | U17: 22.11.2018 | W17: 07.05.2020
A18: 4c O 17/19 | B18: Duesseldorf | C18: Yes | D18: Yes | E18: No? | F18: Yes | G18: https://www.katheraugenstein.com:443/app/uploads/2020-11-26-LG-Duesseldorf-4c-O-17_19_DE.pdf | H18: https://www.katheraugenstein.com:443/app/uploads/2020-11-26-LG-Duesseldorf-4c-O-17_19_EN.pdf | I18: Yes | J18: Yes | K18: http://www.justiz.nrw.de/nrwe/lgs/duesseldorf/lg_duesseldorf/j2020/4c_O_17_19_Beschluss_20201126.html | L18: - | M18: 15.03.2019 | N18: 26.11.2020 | Q18: ? | T18: 21.03.2019 | U18: 21.03.2019 | W18: 26.11.2020
A19: 7 O 96/14 | B19: Mannheim | C19: Yes | D19: Yes | E19: Yes | F19: Yes | G19: https://openjur.de/u/884742.html | H19: - | I19: Yes | J19: Yes | K19: http://lrbw.juris.de/cgi-bin/laender_rechtsprechung/document.py?Gericht=bw&GerichtAuswahl=Landgerichte&Art=en&sid=0790c421fe7d2d5a437b3b2305786018&nr=20517&anz=1&pos=0&Blank=1 | L19: 6 U 55/16 | M19: 01.07.2014 | N19: 08.01.2016 | O19: 1 | Q19: - | T19: 22.06.2014 | U19: 22.06.2014 | W19: 08.01.2016
A20: 7 O 66/15 | B20: Mannheim | C20: Yes | D20: Yes | E20: Yes | F20: Yes | G20: https://openjur.de/u/878158.html | H20: - | I20: Yes | J20: Yes | K20: http://lrbw.juris.de/cgi-bin/laender_rechtsprechung/document.py?Gericht=bw&GerichtAuswahl=Landgerichte&Art=en&sid=8366362dbe6de75dedf5f0aa93fa55fa&nr=20430&anz=1&pos=0&Blank=1 | L20: - | M20: 15.04.2015 | N20: 29.01.2016 | O20: ? | Q20: - | T20: 05.04.2015 | U20: 05.04.2015 | W20: 29.01.2016
A21: 7 O 115/16 | B21: Mannheim | C21: Yes! | D21: Yes | E21: Yes | F21: Yes | G21: https://www.katheraugenstein.com:443/app/uploads/DE-LG-Mannheim-7-O-115-16.pdf | H21: https://www.katheraugenstein.com:443/app/uploads/EN-Regional-Court-Mannheim-7-O-115-16.pdf | I21: Yes | J21: No | K21: - | L21: - | M21: 04.10.2016 | N21: 04.09.2019 | Q21: - | T21: 02.07.2016 | U21: 02.07.2016 | W21: 04.09.2019
A22: 7 O 165/16 | B22: Mannheim | C22: Yes! | D22: Yes | E22: No | F22: Yes | G22: https://www.katheraugenstein.com:443/app/uploads/2018-07-13-7-O-165_16-DE-pdf-2.pdf | H22: https://www.katheraugenstein.com:443/app/uploads/2018-09-28-7-O-165_16-EN-pdf-1-2.pdf | I22: Yes | J22: No | K22: - | L22: - | M22: 30.01.2017 | N22: 13.07.2018 | Q22: - | T22: 23.09.2016 | U22: 23.09.2016 | W22: 13.07.2018
A23: 7 O 19/16 | B23: Mannheim | C23: Yes | D23: Yes | E23: No | F23: Yes | G23: https://www.katheraugenstein.com:443/app/uploads/2016-11-17-7-O-19_16-DE-pdf-3.pdf | H23: https://www.katheraugenstein.com:443/app/uploads/2016-11-17-7-O-19_16-EN-pdf-3.pdf | I23: Yes | J23: Yes | K23: http://lrbw.juris.de/cgi-bin/laender_rechtsprechung/document.py?Gericht=bw&GerichtAuswahl=Landgerichte&Art=en&sid=6e6a9d26ac6aee935c628e75dd026e34&nr=21539&anz=1&pos=0&Blank=1 | L23: - | M23: 16.10.2015 | N23: 17.11.2016 | Q23: - | T23: 19.01.2016 | U23: 19.01.2016 | W23: 17.11.2016
A24: 7 O 209/15 | B24: Mannheim | C24: Yes | D24: Yes | E24: No | F24: Yes | G24: http://lrbw.juris.de/cgi-bin/laender_rechtsprechung/document.py?Gericht=bw&nr=21580 | H24: - | I24: Yes | J24: Yes (no search) | K24: http://lrbw.juris.de/cgi-bin/laender_rechtsprechung/document.py?Gericht=bw&Datum=2023&nr=21580&Blank=1 | L24: - | M24: 16.10.2015 | N24: 17.11.2016 | Q24: - | T24: 31.10.2015 | U24: 31.10.2015 | W24: 17.11.2016
A25: 7 O 18/17 | B25: Mannheim | C25: Yes! | D25: Yes | E25: No | F25: Yes | G25: https://www.katheraugenstein.com:443/app/uploads/2018-03-02-7-O-18-17-DE-KBR-Richtig.pdf | H25: https://www.katheraugenstein.com:443/app/uploads/2018-03-02-7-O-18_17-EN-pdf.pdf | I25: Yes | J25: No | K25: - | L25: - | M25: 29.11.2016 | N25: 02.03.2018 | Q25: - | T25: 29.01.2017 | U25: 29.01.2017 | W25: 02.03.2018
A26: 2 O 136/18 | B26: Mannheim | C26: Yes!* | D26: Yes | E26: No | F26: Yes | G26: https://www.katheraugenstein.com:443/app/uploads/2020-08-21-LG-Mannheim-2-O-136_18-DE.pdf | H26: https://www.katheraugenstein.com:443/app/uploads/2020-08-21-LG-Mannheim-2-O-136_18-EN.pdf | I26: Yes | J26: No | K26: - | L26: - | M26: 01.03.2018 | N26: 21.08.2020 | Q26: - | T26: 17.10.2018 | U26: 17.10.2018 | W26: 21.08.2020
A27: 2 O 131/19 | B27: Mannheim | C27: Yes* | D27: Yes? | E27: No? | F27: Yes | G27: https://www.katheraugenstein.com:443/app/uploads/2021-03-02-LG-Mannheim-2-O-131-19-DE.pdf | H27: https://www.katheraugenstein.com:443/app/uploads/2021-03-02-LG-Mannheim-2-O-131-19-EN.pdf | I27: Yes | J27: No | K27: - | L27: - | M27: 15.11.2019 | N27: 02.03.2021 | Q27: - | W27: 02.03.2021
A28: 2 O 34/19 | B28: Mannheim | C28: Yes! | D28: Yes | E28: Yes | F28: Yes | G28: https://www.katheraugenstein.com:443/app/uploads/2020-08-18-LG-Mannheim-2-O-34_19-DE.pdf | H28: https://www.katheraugenstein.com:443/app/uploads/2020-08-18-LG-Mannheim-2-O-34_19-EN.pdf | I28: Yes | J28: No | K28: - | L28: - | M28: 01.04.2019 | N28: 18.08.2020 | Q28: - | T28: 21.03.2019 | U28: 21.03.2019 | W28: 18.08.2020
A29: 7 O 36/21 | B29: Munich | C29: Yes | D29: Yes? | E29: ?? | F29: Yes | G29: https://www.katheraugenstein.com:443/app/uploads/2021-06-24-LG-Muenchen-7-O-36-21-DE.pdf | H29: https://www.katheraugenstein.com:443/app/uploads/2021-06-24-RC-Munich-7-O-36-21-EN.pdf | I29: Yes | J29: Yes | K29: https://www.gesetze-bayern.de/Content/Document/Y-300-Z-GRURRS-B-2021-N-17662?hl=true | L29: - | N29: 24.06.2021 | P29: 1 | Q29: - | W29: 24.06.2021
A30: 7 O 14276/20 | B30: Munich | C30: Yes | D30: Yes? | E30: ?? | F30: Yes | G30: https://www.katheraugenstein.com:443/app/uploads/2021-01-28-LG-Muenchen-I-7-O-14276-20-DE.pdf | H30: https://www.katheraugenstein.com:443/app/uploads/2021-01-28-LG-Muenchen-I-7-O-14276-20-EN.pdf | I30: Yes | J30: Yes | K30: https://www.gesetze-bayern.de/Content/Document/Y-300-Z-GRURRS-B-2021-N-3995?hl=true | L30: - | N30: 28.01.2021 | P30: 1 | Q30: - | T30: 30.10.2020 | U30: 30.10.2020
A31: 7 O 8818/19 | B31: Munich | C31: Yes | D31: Yes | E31: Yes | F31: Yes | G31: https://www.katheraugenstein.com:443/app/uploads/2020-09-10-LG-Muenchen-7-O-8818_19-DE.pdf | H31: https://www.katheraugenstein.com:443/app/uploads/2020-09-10-LG-Muenchen-7-O-8818_19-EN.pdf | I31: Yes | J31: Yes | K31: https://www.gesetze-bayern.de/Content/Document/Y-300-Z-GRURRS-B-2020-N-22577?hl=true | L31: - | M31: 15.11.2019 | N31: 10.09.2020 | Q31: - | T31: 28.06.2019 | U31: 28.06.2019 | W31: 10.09.2020
A32: 7 O 15350/19 | B32: Munich | C32: Yes | D32: Yes | E32: Yes | F32: No | G32: - | H32: - | J32: Yes | K32: https://www.gesetze-bayern.de/Content/Document/Y-300-Z-GRURRS-B-2021-N-23157 | L32: - | M32: 19.02.2021 | N32: 19.08.2021 | Q32: - | T32: 10.10.2019 | U32: 10.10.2019 | W32: 19.08.2021

Sheet Sheet2
A1: Aktenzeichen | B1: Landgericht | C1: Verfügbar | D1: Die Beklagte wird verurteilt zu unterlassen | E1: Entscheidung (Untrelassung) | F1: Kather Augenstein | G1: Link DE | H1: Link EN | I1: Darts-IP | J1: eJustiz | K1: Link | L1: Zugehörigen Aktenzeichen | M1: Klage auf Unterlassung | N1: Urteil | O1: Prehuawei | P1: AASI | Q1: Streitwert | S1: First contact | T1: Date of complaint | U1: First notice of infringement (first complaint) | V1: First licensing offer | W1: Date of decision | X1: Dominant position | Y1: Abuse of dominant position | Z1: Notice of Infringement | AA1: Willingness to license | AB1: FRAND offer | AC1: Pool | AD1: Worldwide
A2: 4c O 24/19 | B2: Duesseldorf | C2: Yes* | D2: Yes? | E2: Yes? | F2: Yes | G2: https://www.katheraugenstein.com/app/uploads/2019-04-24-4c-O-24_19-DE.pdf | H2: https://www.katheraugenstein.com/app/uploads/2019-04-24-4c-O-24_19-EN.pdf | I2: Yes | J2: No | K2: - | L2: - | M2: ? | N2: 24.04.2019 | Q2: 1000000
A3: 2 O 75/21 | B3: Mannheim | C3: Yes* | D3: Yes | E3: Yes | F3: Yes | G3: https://www.katheraugenstein.com/app/uploads/2022-07-05-LG-Mannheim-2-O-75_21-LTE-Mobilfunkstandard.pdf | H3: https://www.katheraugenstein.com/app/uploads/2022-07-05-Regional-Court-Mannheim-2-O-75_21-LTE-Mobilfunkstandard-EN.pdf | I3: Yes | J3: No | K3: - | L3: - | M3: 08.07.2021 | N3: 05.07.2022 | Q3: - | T3: 08.07.2021 | U3: 08.07.2021
A4: 7 O 91/22 | B4: Mannheim | C4: Yes* | D4: ?? | E4: ?? | F4: Yes | G4: https://www.katheraugenstein.com/app/uploads/2023-08-01-Landgericht-Mannheim-Beschluss-vom-14.04.2023-Az.-7-O-91_22.pdf | H4: https://www.katheraugenstein.com/app/uploads/2023-08-01-Regional-Court-Mannheim_-Decision-14.04.2023_-Az.-7-O-91_22.pdf | I4: Yes | J4: No | K4: - | L4: - | M4: ? | N4: 14.04.2023 | Q4: -
A5: 7 O 28/16 | B5: Mannheim | C5: Yes! | D5: Yes | E5: No? | F5: Yes | G5: https://www.katheraugenstein.com/app/uploads/2017-11-10-7-O-28_16-DE-pdf-1.pdf | H5: https://www.katheraugenstein.com/app/uploads/2017-11-10-7-O-28_16-EN-pdf-1.pdf | I5: Yes | J5: No | K5: - | L5: - | M5: 03.02.2016 | N5: 10.11.2017 | Q5: - | T5: 03.02.2016 | U5: 03.02.2016
A6: 2 O 106/14 | B6: Mannheim | C6: Yes | D6: Yes | E6: Yes | F6: Yes | G6: https://www.katheraugenstein.com/app/uploads/2015-11-27-2-O-106_-14-DE-pdf.pdf | H6: https://www.katheraugenstein.com/app/uploads/2015-11-27-2-O-106_14-EN-pdf-1.pdf | I6: Yes | J6: Yes | K6: http://lrbw.juris.de/cgi-bin/laender_rechtsprechung/document.py?Gericht=bw&GerichtAuswahl=Landgerichte&Art=en&sid=f3caef45b2432c5f65740b9bb5cc38da&nr=20078&anz=1&pos=0&Blank=1 | L6: - | M6: 15.06.2014 | N6: 27.11.2015 | O6: 1 | Q6: - | T6: 15.06.2014 | U6: 15.06.2014
A7: 21 O 11522/21 | B7: Munich | C7: Yes | D7: Yes | E7: Yes | F7: Yes | G7: https://www.katheraugenstein.com/app/uploads/LG-Muenchen-I-05.08.2022-21-O-11522_21-Pitch-Lag-Schaetzung.pdf | H7: https://www.katheraugenstein.com/app/uploads/LG-Muenchen-I-05.08.2022-21-O-11522_21-Pitch-Lag-Schaetzung-EN.pdf | I7: Yes | J7: Yes | K7: https://www.gesetze-bayern.de/Content/Document/Y-300-Z-GRURRS-B-2022-N-26267?hl=true | L7: 21 O 8879/21; 21 O 8890/21 | M7: 23.03.2022 | N7: 05.08.2022 | Q7: -
A8: 7 O 14912/19 | B8: Munich | C8: Yes | D8: No? | E8: No | F8: Yes | G8: https://www.katheraugenstein.com/app/uploads/2022-05-25-LG-Muenchen-I-7-O-14091_19-Sprachsignalcodierer-II.pdf | H8: https://www.katheraugenstein.com/app/uploads/2022-05-25-Regional-Court-Munich-I-7-O-14091_19-Sprachsignalcodierer-II-EN.pdf | I8: Yes | J8: Yes | K8: https://www.gesetze-bayern.de/Content/Document/Y-300-Z-GRURRS-B-2022-N-13480?hl=true | L8: - | M8: 16.09.2019 | N8: 25.05.2022 | Q8: -
A9: 21 O 1910/22 | B9: Munich | C9: Yes | D9: Yes | E9: Yes | F9: Yes | G9: https://www.katheraugenstein.com/app/uploads/2023-04-19-LG-Muenchen-I-21-O-1910_22-Rahmenloeschung.pdf | H9: https://www.katheraugenstein.com/app/uploads/2023-04-19-Regional-Court-Munich-I-21-O-1910_22-Rahmenloeschung_en.pdf | I9: Yes | J9: Yes | K9: https://www.gesetze-bayern.de/Content/Document/Y-300-Z-GRURRS-B-2023-N-18036?hl=true | L9: - | M9: 18.01.2023 | N9: 19.04.2023 | Q9: -
A10: 21 O 4140/21 | B10: Munich | C10: Yes | D10: Yes | E10: Yes | F10: Yes | G10: https://www.katheraugenstein.com/app/uploads/2023-02-17-LG-Muenchen-21-O-4140_21.pdf | H10: https://www.katheraugenstein.com/app/uploads/2023-02-17-Regional-Court-Munich-21-O-4140_21.pdf | I10: Yes | J10: Yes | K10: https://www.gesetze-bayern.de/Content/Document/Y-300-Z-GRURRS-B-2023-N-11247?hl=true | L10: - | M10: 21.09.2022/ | N10: 17.02.2023 | Q10: -
A11: 21 O 9333/19 | B11: Munich | C11: Yes | D11: Yes? | E11: ?? | F11: Yes | G11: https://www.katheraugenstein.com/app/uploads/DE-21-O-9333-19.pdf | H11: https://www.katheraugenstein.com/app/uploads/EN-21-O-9333-19.pdf | I11: Yes | J11: Yes | K11: https://www.gesetze-bayern.de/Content/Document/Y-300-Z-BECKRS-B-2019-N-25536?hl=true | L11: - | M11: ? | N11: 11.07.2019 | P11: 1 | Q11: -
A12: 7 O 8818/19 | B12: Munich | C12: Yes | D12: Yes | E12: Yes | F12: Yes | G12: https://www.katheraugenstein.com/app/uploads/2020-09-10-LG-Muenchen-7-O-8818_19-DE.pdf | H12: https://www.katheraugenstein.com/app/uploads/2020-09-10-LG-Muenchen-7-O-8818_19-EN.pdf | I12: Yes | J12: Yes | K12: https://www.gesetze-bayern.de/Content/Document/Y-300-Z-GRURRS-B-2020-N-22577?hl=true | L12: - | M12: 28.06.2019 | N12: 10.09.2020 | Q12: - | T12: 28.06.2019 | U12: 28.06.2019
M13: all of these should be checked

Sheet Sheet3
A1: Aktenzeichen | B1: Landgericht | C1: Verfügbar | D1: Die Beklagte wird verurteilt zu unterlassen | E1: Entscheidung (Untrelassung) | F1: Kather Augenstein | G1: Link DE | H1: Link EN | I1: Darts-IP | J1: eJustiz | K1: Link | L1: Zugehörigen Aktenzeichen | M1: Klage auf Unterlassung | N1: Urteil | O1: Prehuawei | P1: AASI | Q1: Streitwert | S1: First contact | T1: Date of complaint | U1: First notice of infringement (first complaint) | V1: First licensing offer | W1: Date of decision | X1: Dominant position | Y1: Abuse of dominant position | Z1: Notice of Infringement | AA1: Willingness to license | AB1: FRAND offer | AC1: Pool | AD1: Worldwide
A2: 4b O 52/14 | B2: Duesseldorf | C2: Yes | D2: No? | E2: No | F2: Yes | G2: https://www.justiz.nrw.de/nrwe/lgs/duesseldorf/lg_duesseldorf/j2016/4b_O_52_14_Schlussurteil_20160119.html | H2: - | I2: Yes | J2: Yes | K2: https://www.justiz.nrw.de/nrwe/lgs/duesseldorf/lg_duesseldorf/j2016/4b_O_52_14_Schlussurteil_20160119.html | L2: - | M2: 14.05.2014 | N2: 19.01.2016 | O2: 1 | Q2: 2000000/1600000 | T2: 14.05.2014 | U2: 14.05.2014
A3: 4a O 27/16 | B3: Duesseldorf | C3: Yes | D3: Yes | E3: No | F3: Yes | G3: https://www.justiz.nrw.de/nrwe/lgs/duesseldorf/lg_duesseldorf/j2017/4a_O_27_16_Urteil_20170713.html | H3: - | I3: Yes | J3: Yes | K3: https://www.justiz.nrw.de/nrwe/lgs/duesseldorf/lg_duesseldorf/j2017/4a_O_27_16_Urteil_20170713.html | L3: - | M3: 18.03.2016 | N3: 13.07.2017 | Q3: 1000000/250000 | T3: 18.03.2016 | U3: 18.03.2016
A4: 4a O 154/15 | B4: Duesseldorf | C4: Yes | D4: Yes | E4: No | F4: Yes | G4: https://www.justiz.nrw.de/nrwe/lgs/duesseldorf/lg_duesseldorf/j2017/4a_O_154_15_Urteil_20170713.html | H4: - | I4: Yes | J4: Yes | K4: https://www.justiz.nrw.de/nrwe/lgs/duesseldorf/lg_duesseldorf/j2017/4a_O_154_15_Urteil_20170713.html | L4: - | M4: 11.06.2015 | N4: 13.07.2017 | O4: ? | Q4: 1000000/250000 | T4: 06.11.2015 | U4: 06.11.2015
A5: 14d O 13/17 | B5: Duesseldorf | C5: Yes | D5: Yes | E5: Yes? | F5: Yes | G5: https://www.justiz.nrw.de/nrwe/lgs/duesseldorf/lg_duesseldorf/j2017/14d_O_13_17_Urteil_20171109.html | H5: - | I5: Yes | J5: Yes | K5: https://www.justiz.nrw.de/nrwe/lgs/duesseldorf/lg_duesseldorf/j2017/14d_O_13_17_Urteil_20171109.html | L5: - | M5: ? | N5: 09.11.2017 | Q5: ?
A6: 7 O 38/14 | B6: Mannheim | C6: Yes! | D6: Yes? | E6: No? | F6: No | G6: - | H6: - | I6: Yes | J6: No | K6: - | L6: - | M6: 21.03.2014 | N6: 26.02.2016 | O6: 1 | Q6: - | T6: 21.03.2014 | U6: 21.03.2014
A7: 7 O 24/14 | B7: Mannheim | C7: Yes! | D7: Yes | E7: Yes | F7: No | G7: - | H7: - | I7: Yes | J7: No | K7: - | L7: - | M7: 26.02.2014 | N7: 21.11.2014/04.03.2016 | O7: 1 | Q7: - | T7: 26.02.2014 | U7: 26.02.2014
A8: 7 O 26/14 | B8: Mannheim | C8: Yes! | D8: Yes | E8: Yes | F8: No | G8: - | H8: - | I8: Yes | J8: No | K8: - | L8: - | M8: 01.03.2014 | N8: 21.11.2014/11.03.2016 | O8: 1 | Q8: - | T8: 01.03.2014 | U8: 01.03.2014
A9: 7 O 298/15 | B9: Mannheim | C9: No | D9: - | E9: - | F9: No | G9: - | H9: - | I9: No | J9: No | K9: - | L9: - | M9: ? | N9: - | Q9: -
A10: 2 O 130/15 | B10: Mannheim | C10: No | D10: - | E10: - | F10: No | G10: - | H10: - | I10: No | J10: No | K10: - | L10: - | M10: ? | N10: - | Q10: -
A11: 2 O 229/15 | B11: Mannheim | C11: Yes! | D11: Yes | E11: Yes | F11: No | G11: - | H11: - | I11: Yes | J11: No | K11: - | L11: - | M11: 09.11.2015 | N11: 25.10.2016 | Q11: - | T11: 09.11.2015 | U11: 09.11.2015
A12: 7 O 43/16 | B12: Mannheim | C12: Yes! | D12: Yes | E12: Yes | F12: No | G12: - | H12: - | I12: Yes | J12: No | K12: - | L12: - | M12: 28.02.2016 | N12: 25.11.2016 | Q12: - | T12: 28.02.2016 | U12: 28.02.2016
A13: 7 O 44/16 | B13: Mannheim | C13: Yes! | D13: Yes | E13: Yes | F13: No | G13: - | H13: - | I13: Yes | J13: No | K13: - | L13: - | M13: 01.03.2016 | N13: 25.11.2016 | Q13: - | T13: 01.03.2016 | U13: 01.03.2016
A14: 7 O 213/15 | B14: Mannheim | C14: No | D14: - | E14: - | F14: No | G14: - | H14: - | I14: No | J14: No | K14: - | L14: - | M14: ? | N14: - | Q14: -
A15: 7 O 212/15 | B15: Mannheim | C15: Yes! | D15: Yes | E15: Yes | F15: No | G15: - | H15: - | I15: Yes | J15: No | K15: - | L15: - | M15: 05.11.2015 | N15: 27.01.2017 | Q15: - | T15: 05.11.2015 | U15: 05.11.2015
A16: 7 O 31/16 | B16: Mannheim | C16: Yes! | D16: Yes | E16: No? | F16: No | G16: - | H16: - | I16: Yes | J16: No | K16: - | L16: - | M16: 08.02.2016 | N16: 24.02.2017 | Q16: - | T16: 08.02.2016 | U16: 08.02.2016
A17: 7 O 98/16 | B17: Mannheim | C17: Yes! | D17: Yes | E17: Yes | F17: No | G17: - | H17: - | I17: Yes | J17: No | K17: - | L17: - | M17: 23.05.2016 | N17: 17.03.2017 | Q17: - | T17: 23.05.2016 | U17: 23.05.2016
A18: 2 O 98/16 | B18: Mannheim | C18: Yes! | D18: Yes | E18: No? | F18: No | G18: - | H18: - | I18: Yes | J18: No | K18: - | L18: - | M18: 09.06.2016 | N18: 23.05.2017 | Q18: -
M19: all of these should be checked

Sheet Sheet4
A1: Aktenzeichen | B1: Landgericht | C1: Verfügbar | D1: Die Beklagte wird verurteilt zu unterlassen | E1: Entscheidung (Untrelassung) | F1: Kather Augenstein | G1: Link DE | H1: Link EN | I1: Darts-IP | J1: eJustiz | K1: Link | L1: Zugehörigen Aktenzeichen | M1: Klage auf Unterlassung | N1: Urteil | O1: Prehuawei | P1: AASI | Q1: Streitwert | S1: First contact | T1: First contact by pool | U1: Date of complaint | V1: First notice of infringement (first contact?) | W1: First licensing offer | X1: Date of decision | Y1: Dominant position | Z1: Abuse of dominant position | AA1: Notice of Infringement | AB1: Willingness to license | AC1: FRAND offer | AD1: Formal | AE1: Substantially | AF1: Pool | AG1: Worldwide | AH1: Further proceedings | AI1: OLG Appeal | AJ1: Result of the appeal | AK1: OLG First instance | AL1: Result of the f.instance | AM1: Bundesgerichtshof | AN1: Result of the Judicial Review | AO1: Patent Validity Proceedings | AP1: Result of the Patent Validity | AQ1: Aktenzeichen Bundespatetgerichts | AR1: Entscheidungsdatum | AS1: Beschwerdesdatum | AT1: Link | AU1: Patents | AV1: Espacenet
A2: 4a O 144/14 | B2: Duesseldorf | C2: Yes | D2: Yes | E2: Yes | F2: No | G2: - | H2: - | I2: Yes | J2: Yes | K2: http://www.justiz.nrw.de/nrwe/lgs/duesseldorf/lg_duesseldorf/j2015/4a_O_144_14_Urteil_20151103.html | L2: I-15 U 41/17 | M2: 08.09.2014 | N2: 03.11.2015 | O2: 1 | Q2: 500000 | S2: 20.12.2012 | U2: 18.12.2014 | V2: 18.12.2014 | W2: 20.12.2012 | X2: 03.11.2015 | Y2: Yes | Z2: No | AA2: Yes | AB2: No | AC2: - | AD2: - | AE2: - | AF2: Yes | AG2: Yes | AH2: Yes | AI2: Yes | AJ2: Reversed in part | AK2: Yes | AL2: LG mirrored | AM2: Yes | AN2: Reversed in part | AO2: Yes | AP2: Invalid for Germany | AQ2: 6 Ni 15/15 (EP) | AR2: 14.02.2018 | AS2: 31.07.2015 | AT2: http://juris.bundespatentgericht.de/cgi-bin/rechtsprechung/document.py?Gericht=bpatg&Art=en&sid=1d78632798b85c831df59d6be5dfa5b4&nr=29853&pos=0&anz=1&Blank=1.pdf | AU2: EP01913904(A), EP1264504 | AV2: DE60130436T2, DE60130436T3
A3: 4a O 126/14 | B3: Duesseldorf | C3: Yes | D3: Yes | E3: Yes | F3: No | G3: - | H3: - | I3: Yes | J3: Yes | K3: http://www.justiz.nrw.de/nrwe/lgs/duesseldorf/lg_duesseldorf/j2016/4a_O_126_14_Teil_Verzichts_und_Schlussurteil_20160331.html | L3: 4a O 73/14; I-15 U 35/16 | M3: 23.07.2014 | N3: 31.03.2016 | O3: 1 | Q3: 2000000 | S3: 31.07.2014 | U3: 12.11.2014 | V3: 12.11.2014 | W3: 22.04.2015 | X3: 31.03.2016 | Y3: Yes | Z3: No | AA3: Yes | AB3: No | AC3: Yes | AD3: Yes | AE3: Yes | AF3: Yes | AG3: Yes | AH3: Yes | AI3: Yes | AJ3: Upheld | AK3: No | AL3: - | AM3: No | AN3: - | AO3: Yes | AP3: - | AQ3: 4 Ni 6/15 (EP), 6 Ni 7/16 (EP), 6 Ni 63/16 (EP), 4 Ni 33/14 (EP) | AR3: - | AS3: 06.11.2014 | AT3: - | AU3: EP99952183(A), EP1125284 | AV3: DE69910058T2, DE69910239T2, DE69910240T2, DE69913724T2
A4: 4a O 73/14 | B4: Duesseldorf | C4: Yes | D4: Yes | E4: Yes | F4: Yes | G4: https://www.katheraugenstein.com/app/uploads/2016-03-31-4a-O-73_14-DE-pdf-2.pdf | H4: https://www.katheraugenstein.com/app/uploads/2016-03-31-4a-O-73_14-EN-pdf-1.pdf | I4: Yes | J4: Yes | K4: http://www.justiz.nrw.de/nrwe/lgs/duesseldorf/lg_duesseldorf/j2016/4a_O_73_14_Teil_Verzichts_und_Schlussurteil_20160331.html | L4: - | M4: 23.07.2014 | N4: 31.03.2016 | O4: 1 | Q4: 2000000 | S4: 31.07.2014 | U4: 23.07.2014 | V4: 23.07.2014 | W4: 22.04.2015 | X4: 31.03.2016 | Y4: Yes | Z4: No | AA4: Yes | AB4: No | AC4: Yes | AD4: Yes | AE4: Yes | AF4: Yes | AG4: Yes | AH4: Yes | AI4: Yes | AJ4: Upheld | AK4: No | AL4: - | AM4: No | AN4: - | AO4: Yes | AP4: Invalid for Germany | AQ4: 6 Ni 6/16 (EP) | AR4: 11.01.2017 | AS4: 04.07.2016 | AT4: http://juris.bundespatentgericht.de/cgi-bin/rechtsprechung/document.py?Gericht=bpatg&Art=en&sid=14e273bb9e03002bf8855902c01530ec&nr=29046&pos=0&anz=1&Blank=1.pdf | AU4: EP99952199(A), EP1125276 | AV4: DE69910058T2, DE69910239T2, DE69910240T2, DE69913724T2
A5: 4a O 16/16 | B5: Duesseldorf | C5: Yes | D5: Yes | E5: No | F5: Yes | G5: https://www.katheraugenstein.com/app/uploads/2017-07-13-4a-O-16_16-DE-pdf-2.pdf | H5: https://www.katheraugenstein.com/app/uploads/2017-07-13-4a-O-16_16-EN-pdf-1.pdf | I5: Yes | J5: Yes | K5: http://www.justiz.nrw.de/nrwe/lgs/duesseldorf/lg_duesseldorf/j2017/4a_O_16_16_Urteil_20170713.html | L5: - | M5: 15.11.2016 | N5: 13.07.2017 | Q5: 1000000 | S5: 04.12.2012 | U5: 18.02.2016 | V5: 04.12.2012 | W5: 04.12.2012 | X5: 13.07.2017 | Y5: Yes | Z5: Yes | AA5: Yes | AB5: Yes | AC5: No | AD5: No | AE5: - | AF5: ? | AG5: Yes | AH5: No | AI5: No | AJ5: - | AK5: No | AL5: - | AM5: No | AN5: - | AO5: Yes | AP5: Invalid for Germany | AQ5: 6 Ni 15/15 (EP) | AR5: 14.02.2018 | AS5: 31.07.2015 | AT5: http://juris.bundespatentgericht.de/cgi-bin/rechtsprechung/document.py?Gericht=bpatg&Art=en&sid=1d78632798b85c831df59d6be5dfa5b4&nr=29853&pos=0&anz=1&Blank=1.pdf | AU5: EP01913904(A), EP1264504 | AV5: DE60130436T2, DE60130436T3
A6: 4a O 35/16 | B6: Duesseldorf | C6: Yes | D6: Yes | E6: No | F6: No | G6: - | H6: - | I6: Yes | J6: Yes | K6: http://www.justiz.nrw.de/nrwe/lgs/duesseldorf/lg_duesseldorf/j2017/4a_O_35_16_Urteil_20170713.html | L6: - | M6: 15.11.2016 | N6: 13.07.2017 | Q6: 1000000 | S6: 04.12.2012 | U6: 09.04.2016 | V6: 09.04.2016 | W6: 04.12.2012 | X6: 13.07.2017 | Y6: Yes | Z6: Yes | AA6: Yes | AB6: Yes | AC6: No | AD6: No | AE6: - | AF6: ? | AG6: Yes | AH6: No | AI6: No | AJ6: - | AK6: No | AL6: - | AM6: No | AN6: - | AO6: Yes | AP6: Invalid for Germany | AQ6: 6 Ni 15/15 (EP) | AR6: 14.02.2018 | AS6: 31.07.2015 | AT6: http://juris.bundespatentgericht.de/cgi-bin/rechtsprechung/document.py?Gericht=bpatg&Art=en&sid=1d78632798b85c831df59d6be5dfa5b4&nr=29853&pos=0&anz=1&Blank=1.pdf | AU6: EP01913904(A), EP1264504 | AV6: DE60130436T2, DE60130436T4
A7: 4c O 72/17 | B7: Duesseldorf | C7: Yes | D7: Yes | E7: No | F7: No | G7: - | H7: - | I7: Yes | J7: Yes | K7: http://www.justiz.nrw.de/nrwe/lgs/duesseldorf/lg_duesseldorf/j2018/4c_O_72_17_Urteil_20180711.html | L7: - | M7: 15.09.2017 | N7: 11.07.2018 | Q7: 4000000 | S7: 25.03.2016 | U7: 25.08.2017 | V7: 25.08.2017 | W7: 25.03.2016 | X7: 11.07.2018 | Y7: Yes | Z7: Yes | AA7: Yes | AB7: Yes | AC7: No | AD7: Yes? | AE7: No | AF7: ? | AG7: ? | AH7: No | AI7: No | AJ7: - | AK7: No | AL7: - | AM7: No | AN7: - | AO7: Yes | AP7: Partially invalid for Germany | AQ7: 5 Ni 50/16 (EP) | AR7: 12.02.2020 | AS7: 26.07.2016 | AT7: http://juris.bundespatentgericht.de/cgi-bin/rechtsprechung/document.py?Gericht=bpatg&Art=en&sid=cceed9fc9f9ffc523f1ae12263bfc901&nr=39046&pos=0&anz=1&Blank=1.pdf | AU7: EP06007976(A), EP1694020(B1) | AV7: DE1161820T1, DE60027414T2
A8: 4c O 77/17 | B8: Duesseldorf | C8: Yes | D8: Yes | E8: No | F8: No | G8: - | H8: - | I8: Yes | J8: Yes | K8: http://www.justiz.nrw.de/nrwe/lgs/duesseldorf/lg_duesseldorf/j2018/4c_O_77_17_Urteil_20180711.html | L8: - | M8: 31.01.2017 | N8: 11.07.2018 | Q8: 4000000 | S8: 25.03.2016 | U8: 11.09.2017 | V8: 11.09.2017 | W8: 25.03.2016 | X8: 11.07.2018 | Y8: Yes | Z8: Yes | AA8: Yes | AB8: Yes | AC8: No | AD8: Yes? | AE8: No | AF8: ? | AG8: ? | AH8: No | AI8: No | AJ8: - | AK8: No | AL8: - | AM8: No | AN8: - | AO8: Yes | AP8: Partially invalid for Germany | AQ8: 5 Ni 50/16 (EP) | AR8: 12.02.2020 | AS8: 26.07.2016 | AT8: http://juris.bundespatentgericht.de/cgi-bin/rechtsprechung/document.py?Gericht=bpatg&Art=en&sid=cceed9fc9f9ffc523f1ae12263bfc901&nr=39046&pos=0&anz=1&Blank=1.pdf | AU8: EP06007976(A), EP1694020 | AV8: DE1161820T1, DE60027414T3
A9: 4a O 15/17 | B9: Duesseldorf | C9: Yes | D9: Yes | E9: Yes | F9: Yes | G9: https://www.katheraugenstein.com/app/uploads/2018-11-09-4a-O-15_17-DE-pdf.pdf | H9: https://www.katheraugenstein.com/app/uploads/2018-11-09-4a-O-15_17-EN-pdf.pdf | I9: Yes | J9: Yes | K9: http://www.justiz.nrw.de/nrwe/lgs/duesseldorf/lg_duesseldorf/j2018/4a_O_15_17_Urteil_20181109.html | L9: - | M9: 15.03.2017 | N9: 09.11.2018 | Q9: 2500000 | S9: 08.09.2011 | U9: 05.02.2017 | V9: 05.02.2017 | W9: 08.09.2011 | X9: 09.11.2018 | Y9: Yes | Z9: No | AA9: Yes | AB9: Yes | AC9: Yes | AD9: Yes | AE9: Yes | AF9: Yes | AG9: Yes | AH9: No | AI9: No | AJ9: - | AK9: No | AL9: - | AM9: No | AN9: - | AO9: No | AP9: - | AQ9: - | AR9: - | AS9: - | AT9: - | AU9: EP04020471(A), EP1487113(B1) | AV9: -
A10: 4c O 3/17 | B10: Duesseldorf | C10: Yes | D10: Yes | E10: Yes | F10: No | G10: - | H10: - | I10: Yes | J10: Yes | K10: http://www.justiz.nrw.de/nrwe/lgs/duesseldorf/lg_duesseldorf/j2018/4c_O_3_17_Urteil_20181221.html | L10: - | M10: 01.04.2017 | N10: 21.12.2018 | Q10: 5000000/30000000 | S10: 03.11.2008 | T10: 03.11.2008 | U10: 11.01.2017 | V10: 06.09.2011 | W10: 06.09.2011 | X10: 21.12.2018 | Y10: Yes | Z10: No | AA10: Yes | AB10: Yes | AC10: Yes | AD10: Yes | AE10: Yes | AF10: Yes | AG10: Yes | AH10: No | AI10: No | AJ10: - | AK10: No | AL10: - | AM10: No | AN10: - | AO10: Yes | AP10: - | AQ10: 2 Ni 36/17 (EP), 2 Ni 19/21 (EP) | AR10: - | AS10: 03.07.2017, 22.04.2021 | AT10: - | AU10: EP03811870(A), EP1569460(B1) | AV10: -
A11: 4a O 17/17 | B11: Duesseldorf | C11: Yes | D11: Yes | E11: Yes | F11: Yes | G11: https://www.katheraugenstein.com/app/uploads/2018-11-09-4a-O-17_17-DE-pdf.pdf | H11: https://www.katheraugenstein.com/app/uploads/2018-11-09-4a-O-17_17-EN-pdf.pdf | I11: Yes | J11: Yes | K11: http://www.justiz.nrw.de/nrwe/lgs/duesseldorf/lg_duesseldorf/j2018/4a_O_17_17_Urteil_20181109.html | L11: - | M11: 01.06.2017 | N11: 09.11.2018 | Q11: 5000000 | S11: 06.09.2011 | U11: 10.02.2017 | V11: 10.02.2017 | W11: 06.09.2011 | X11: 09.11.2018 | Y11: Yes | Z11: No | AA11: Yes | AB11: Yes | AC11: Yes | AD11: Yes | AE11: Yes | AF11: Yes | AG11: Yes | AH11: Yes | AI11: Yes | AJ11: Withdrawn | AK11: No | AL11: - | AM11: No | AN11: - | AO11: Yes | AP11: - | AQ11: 2 Ni 66/17 (EP), 7 Ni 21/19 (EP) | AR11: - | AS11: 19.10.2017 | AT11: - | AU11: EP07100277(A), EP1773067(B1) | AV11: DE60320243T2
A12: 4c O 81/17 | B12: Duesseldorf | C12: Yes | D12: Yes | E12: No | F12: Yes | G12: https://www.katheraugenstein.com:443/app/uploads/2018-07-11-4c-O-81_17-DE-pdf-2.pdf | H12: https://www.katheraugenstein.com:443/app/uploads/2018-07-11-4c-O-81_17-EN-pdf-2.pdf | I12: Yes | J12: Yes | K12: http://www.justiz.nrw.de/nrwe/lgs/duesseldorf/lg_duesseldorf/j2018/4c_O_81_17_Urteil_20180711.html | L12: - | M12: 15.06.2016 | N12: 11.07.2018 | Q12: 4000000 | S12: 06.10.2015 | U12: 24.09.2017 | V12: 24.09.2017 | W12: 27.01.2016 | X12: 11.07.2018 | Y12: Yes | Z12: Yes | AA12: Yes | AB12: Yes | AC12: No | AD12: Yes? | AE12: No | AF12: ? | AG12: ? | AH12: Yes | AI12: Yes* | AJ12: Reversed and remand | AK12: No | AL12: - | AM12: No | AN12: - | AO12: Yes | AP12: Partially invalid for Germany | AQ12: 5 Ni 50/16 (EP) | AR12: 12.02.2020 | AS12: 26.07.2016 | AT12: http://juris.bundespatentgericht.de/cgi-bin/rechtsprechung/document.py?Gericht=bpatg&Art=en&sid=cceed9fc9f9ffc523f1ae12263bfc901&nr=39046&pos=0&anz=1&Blank=1.pdf | AU12: EP06007976(A), EP1694020(B1) | AV12: DE1161820T1, DE60027414T2
A13: 4c O 12/17 | B13: Duesseldorf | C13: Yes | D13: Yes | E13: Yes | F13: No | G13: - | H13: - | I13: Yes | J13: Yes | K13: http://www.justiz.nrw.de/nrwe/lgs/duesseldorf/lg_duesseldorf/j2019/4c_O_12_17_Urteil_20190108.html | L13: - | M13: 01.04.2017 | N13: 08.01.2019 | Q13: 30000000/10000000 | S13: 06.09.2011 | U13: 10.02.2017 | V13: 10.02.2017 | W13: 06.09.2011 | X13: 08.01.2019 | Y13: Yes | Z13: No | AA13: Yes | AB13: Yes | AC13: Yes | AD13: Yes | AE13: Yes | AF13: Yes | AG13: Yes | AH13: No | AI13: No | AJ13: - | AK13: No | AL13: - | AM13: No | AN13: - | AO13: Yes | AP13: - | AQ13: 2 Ni 48/17 (EP), 2 Ni 51/17 (EP) | AR13: - | AS13: 24.08.2017 | AT13: - | AU13: EP07022122(A), EP1887806(B1) | AV13: -
A14: 4c O 44/18 | B14: Duesseldorf | C14: Yes | D14: Yes | E14: Yes | F14: No | G14: - | H14: - | I14: Yes | J14: Yes | K14: http://www.justiz.nrw.de/nrwe/lgs/duesseldorf/lg_duesseldorf/j2020/4c_O_44_18_Urteil_20200507.html | L14: - | M14: 01.10.2018 | N14: 07.05.2020 | Q14: 1000000 | S14: ? | T14: earlier (date unknown) [para 34] | W14: 11.07.2018 | X14: 07.05.2020 | Y14: Yes | Z14: No | AA14: Yes | AB14: Yes | AC14: Yes | AD14: Yes | AE14: Yes | AF14: Yes | AG14: Yes | AH14: Yes | AI14: No | AJ14: - | AK14: Yes | AL14: Same | AM14: No | AN14: - | AO14: Yes | AP14: Invalid for Germany | AQ14: 2 Ni 39/21 (EP) | AR14: 16.03.2023 | AS14: 29.03.2019 | AT14: http://juris.bundespatentgericht.de/cgi-bin/rechtsprechung/document.py?Gericht=bpatg&Art=en&sid=2a46cbd669d30945f37f9bc0306cdede&nr=43699&pos=0&anz=1&Blank=1.pdf | AU14: EP12794438(A), EP2777270 | AV14: -
A15: 4c O 56/18 | B15: Duesseldorf | C15: Yes | D15: Yes | E15: Yes | F15: No | G15: - | H15: - | I15: Yes | J15: Yes | K15: http://www.justiz.nrw.de/nrwe/lgs/duesseldorf/lg_duesseldorf/j2020/4c_O_56_18_Urteil_20200507.html | L15: - | M15: 01.10.2018 | N15: 07.05.2020 | Q15: 1000000 | S15: ? | T15: earlier (date unknown) [para 31] | U15: 24.09.2018 | V15: 24.09.2018 | W15: 03.09.2018 | X15: 07.05.2020 | Y15: Yes | Z15: No | AA15: Yes | AB15: Yes | AC15: Yes | AD15: Yes | AE15: Yes | AF15: Yes | AG15: Yes | AH15: No | AI15: No | AJ15: - | AK15: No | AL15: - | AM15: No | AN15: - | AO15: Yes | AP15: Partially invalid for Germany | AQ15: 2 Ni 7/21 (EP) | AR15: 27.01.2023 | AS15: 08.04.2019 | AT15: http://juris.bundespatentgericht.de/cgi-bin/rechtsprechung/document.py?Gericht=bpatg&Art=en&sid=512d6819bb3a9180b75a48161f5aff05&nr=43641&pos=0&anz=1&Blank=1.pdf | AU15: EP11714644(A), EP2559245 | AV15: -
A16: 4c O 69/18 | B16: Duesseldorf | C16: Yes | D16: Yes | E16: Yes | F16: No | G16: - | H16: - | I16: Yes | J16: Yes | K16: http://www.justiz.nrw.de/nrwe/lgs/duesseldorf/lg_duesseldorf/j2020/4c_O_69_18_Anerkenntnisurteil_20200507.html | L16: - | M16: 01.12.2018 | N16: 07.05.2020 | Q16: 1000000 | S16: ? | T16: earlier (date unknown) [para 37] | U16: 22.11.2018 | V16: 22.11.2018 | W16: 07.11.2017 | X16: 07.05.2020 | Y16: Yes | Z16: No | AA16: Yes | AB16: Yes | AC16: Yes | AD16: Yes | AE16: Yes | AF16: Yes | AG16: Yes | AH16: No | AI16: No | AJ16: - | AK16: No | AL16: - | AM16: No | AN16: - | AO16: Yes | AP16: - | AQ16: 5 Ni 7/19 (EP) | AR16: - | AS16: 24.07.2019 | AT16: - | AU16: EP03751150(A), EP1557072 | AV16: -
A17: 4c O 17/19 | B17: Duesseldorf | C17: Yes | D17: Yes | E17: n./a. | F17: Yes | G17: https://www.katheraugenstein.com:443/app/uploads/2020-11-26-LG-Duesseldorf-4c-O-17_19_DE.pdf | H17: https://www.katheraugenstein.com:443/app/uploads/2020-11-26-LG-Duesseldorf-4c-O-17_19_EN.pdf | I17: Yes | J17: Yes | K17: http://www.justiz.nrw.de/nrwe/lgs/duesseldorf/lg_duesseldorf/j2020/4c_O_17_19_Beschluss_20201126.html | L17: - | M17: 15.03.2019 | N17: 26.11.2020 | Q17: ? | S17: 01.03.2016 | U17: 21.03.2019 | V17: 21.03.2019 | W17: 09.11.2016 | X17: 26.11.2020 | Y17: ? | Z17: ? | AA17: Yes | AB17: Yes | AC17: ? | AD17: ? | AE17: ? | AF17: Yes | AG17: ? | AH17: No | AI17: No | AJ17: - | AK17: No | AL17: - | AM17: No | AN17: - | AO17: Yes | AP17: Invalid for Germany | AQ17: 2 Ni 37/20 (EP) | AR17: 17.03.2022 | AS17: 26.07.2019? | AT17: http://juris.bundespatentgericht.de/cgi-bin/rechtsprechung/document.py?Gericht=bpatg&Art=en&sid=53950807634dcf53171690d1a110fef0&nr=43025&pos=0&anz=1&Blank=1.pdf | AU17: EP07804979(A), EP2087629(B1) | AV17: -
A18: 7 O 96/14 | B18: Mannheim | C18: Yes | D18: Yes | E18: Yes | F18: Yes | G18: https://openjur.de/u/884742.html | H18: - | I18: Yes | J18: Yes | K18: http://lrbw.juris.de/cgi-bin/laender_rechtsprechung/document.py?Gericht=bw&GerichtAuswahl=Landgerichte&Art=en&sid=0790c421fe7d2d5a437b3b2305786018&nr=20517&anz=1&pos=0&Blank=1 | L18: 6 U 55/16 | M18: 01.07.2014 | N18: 08.01.2016 | O18: 1 | Q18: - | S18: 2013 | U18: 22.06.2014 | V18: 22.06.2014 | W18: 2013 | X18: 08.01.2016 | Y18: Yes | Z18: No | AA18: Yes | AB18: No | AC18: Yes | AD18: Yes | AE18: Yes | AF18: Yes | AG18: Yes | AH18: Yes | AI18: Yes | AJ18: Reversed in part | AK18: No | AL18: - | AM18: No | AN18: - | AO18: Yes | AP18: - | AQ18: 2 Ni 23/16, 2 Ni 38/17 (EP), 2 Ni 10/15 (EP) | AR18: - | AS18: 05.06.2015 | AT18: - | AU18: EP02021307(A), EP1267348 | AV18: DE69719582T2
A19: 7 O 66/15 | B19: Mannheim | C19: Yes | D19: Yes | E19: Yes | F19: Yes | G19: https://openjur.de/u/878158.html | H19: - | I19: Yes | J19: Yes | K19: http://lrbw.juris.de/cgi-bin/laender_rechtsprechung/document.py?Gericht=bw&GerichtAuswahl=Landgerichte&Art=en&sid=8366362dbe6de75dedf5f0aa93fa55fa&nr=20430&anz=1&pos=0&Blank=1 | L19: - | M19: 15.04.2015 | N19: 29.01.2016 | O19: 1 | Q19: - | S19: 19.03.2014 | U19: 05.04.2015 | V19: 05.04.2015 | W19: 19.03.2014 | X19: 29.01.2016 | Y19: Yes | Z19: No | AA19: Yes | AB19: No | AC19: Yes | AD19: Yes | AE19: Yes | AF19: Yes | AG19: Yes | AH19: No | AI19: No | AJ19: - | AK19: No | AL19: - | AM19: No | AN19: - | AO19: Yes | AP19: - | AQ19: 5 Ni 30/15 (EP) | AR19: - | AS19: 03.07.2015 | AT19: - | AU19: EP08000573(A), EP1914945 | AV19: DE602006000464T2
A20: 7 O 115/16 | B20: Mannheim | C20: Yes! | D20: Yes | E20: Yes | F20: Yes | G20: https://www.katheraugenstein.com:443/app/uploads/DE-LG-Mannheim-7-O-115-16.pdf | H20: https://www.katheraugenstein.com:443/app/uploads/EN-Regional-Court-Mannheim-7-O-115-16.pdf | I20: Yes | J20: No | K20: - | L20: - | M20: 04.10.2016 | N20: 04.09.2019 | Q20: - | S20: 01.06.2015 | U20: 02.07.2016 | V20: 02.07.2016 | W20: 01.06.2016 | X20: 04.09.2019 | Y20: Yes | Z20: - | AA20: Yes | AB20: No | AC20: Yes | AD20: ? | AE20: ? | AF20: Yes | AG20: Yes | AH20: Yes | AI20: Yes | AJ20: Reversed in part | AK20: No | AL20: - | AM20: No | AN20: - | AO20: Yes | AP20: Partially invalid for Germany | AQ20: 6 Ni 70/16 (EP) | AR20: 17.10.2018 | AS20: 10.11.2016 | AT20: http://juris.bundespatentgericht.de/cgi-bin/rechtsprechung/document.py?Gericht=bpatg&Art=en&sid=72dab1f480256d994d46d296e1d81f0e&nr=34383&pos=0&anz=1&Blank=1.pdf | AU20: EP99947502(A), EP1119997(B1) | AV20: DE69924130C5, DE69924130T2
A21: 7 O 165/16 | B21: Mannheim | C21: Yes! | D21: Yes | E21: No | F21: Yes | G21: https://www.katheraugenstein.com:443/app/uploads/2018-07-13-7-O-165_16-DE-pdf-2.pdf | H21: https://www.katheraugenstein.com:443/app/uploads/2018-09-28-7-O-165_16-EN-pdf-1-2.pdf | I21: Yes | J21: No | K21: - | L21: - | M21: 30.01.2017 | N21: 13.07.2018 | Q21: - | S21: 15.12.2014 | U21: 23.09.2016 | V21: 23.09.2016 | W21: 03.08.2015 | X21: 13.07.2018 | Y21: Yes | Z21: ? | AA21: Yes | AB21: Yes | AC21: No | AD21: No | AE21: - | AF21: ? | AG21: Yes | AH21: Yes | AI21: Yes | AJ21: Upheld | AK21: No | AL21: - | AM21: Yes | AN21: Reversed and remand | AO21: Yes | AP21: Partially invalid for Germany | AQ21: 2 Ni 14/17 (EP) | AR21: 19.09.2019 | AS21: 10.03.2017? | AT21: http://juris.bundespatentgericht.de/cgi-bin/rechtsprechung/document.py?Gericht=bpatg&Art=en&sid=75f141e9346b099fa6b6be07eb8d05a5&nr=39474&pos=0&anz=1&Blank=1.pdf | AU21: EP09741793(A), EP2294737 | AV21: -
A22: 7 O 19/16 | B22: Mannheim | C22: Yes | D22: Yes | E22: No | F22: Yes | G22: https://www.katheraugenstein.com:443/app/uploads/2016-11-17-7-O-19_16-DE-pdf-3.pdf | H22: https://www.katheraugenstein.com:443/app/uploads/2016-11-17-7-O-19_16-EN-pdf-3.pdf | I22: Yes | J22: Yes | K22: http://lrbw.juris.de/cgi-bin/laender_rechtsprechung/document.py?Gericht=bw&GerichtAuswahl=Landgerichte&Art=en&sid=6e6a9d26ac6aee935c628e75dd026e34&nr=21539&anz=1&pos=0&Blank=1 | L22: - | M22: 16.10.2015 | N22: 17.11.2016 | Q22: - | S22: 05.07.2014 | U22: 19.01.2016 | V22: 19.01.2016 | W22: 28.07.2015 | X22: 17.11.2016 | Y22: Yes | Z22: Yes | AA22: Yes | AB22: Yes | AC22: No | AD22: No | AE22: - | AF22: ? | AG22: Yes | AH22: No | AI22: No | AJ22: - | AK22: No | AL22: - | AM22: No | AN22: - | AO22: Yes | AP22: Invalid for Germany | AQ22: 2 Ni 10/17 (EP) | AR22: 25.03.2019 | AS22: 08.04.2016 | AT22: http://juris.bundespatentgericht.de/cgi-bin/rechtsprechung/document.py?Gericht=bpatg&Art=en&sid=b33d1bbc43fde716904fd6352120093b&nr=34377&pos=0&anz=1&Blank=1.pdf | AU22: EP02775087(A), EP1440525 | AV22: -
A23: 7 O 209/15 | B23: Mannheim | C23: Yes | D23: Yes | E23: No | F23: Yes | G23: http://lrbw.juris.de/cgi-bin/laender_rechtsprechung/document.py?Gericht=bw&nr=21580 | H23: - | I23: Yes | J23: Yes (no search) | K23: http://lrbw.juris.de/cgi-bin/laender_rechtsprechung/document.py?Gericht=bw&Datum=2023&nr=21580&Blank=1 | L23: - | M23: 16.10.2015 | N23: 17.11.2016 | Q23: - | S23: 05.07.2014 | U23: 31.10.2015 | V23: 31.10.2015 | W23: 28.07.2015 | X23: 17.11.2016 | Y23: Yes | Z23: Yes | AA23: Yes | AB23: Yes | AC23: No | AD23: No | AE23: - | AF23: ? | AG23: Yes | AH23: No | AI23: No | AJ23: - | AK23: No | AL23: - | AM23: No | AN23: - | AO23: Yes | AP23: Partially invalid for Germany | AQ23: 6 Ni 39/16 (EP) | AR23: 13.11.2018 | AS23: 24.03.2016 | AT23: http://juris.bundespatentgericht.de/cgi-bin/rechtsprechung/document.py?Gericht=bpatg&Art=en&sid=b7368e91684c1e0fa0058a1a34d5c60a&nr=33531&pos=1&anz=4&Blank=1.pdf | AU23: EP99969233(A), EP1062745(B1); EP99964682(A), EP1062743(B1) | AV23: DE69933654T2, DE69934577T2, DE69935715T2
A24: 7 O 18/17 | B24: Mannheim | C24: Yes! | D24: Yes | E24: No | F24: Yes | G24: https://www.katheraugenstein.com:443/app/uploads/2018-03-02-7-O-18-17-DE-KBR-Richtig.pdf | H24: https://www.katheraugenstein.com:443/app/uploads/2018-03-02-7-O-18_17-EN-pdf.pdf | I24: Yes | J24: No | K24: - | L24: - | M24: 29.11.2016 | N24: 02.03.2018 | Q24: - | S24: 13.10.2014 | U24: 29.01.2017 | V24: 29.01.2017 | W24: 28.07.2015 | X24: 02.03.2018 | Y24: Yes | Z24: Yes | AA24: Yes | AB24: No | AC24: - | AD24: - | AE24: - | AF24: ? | AG24: Yes | AH24: No | AI24: No | AJ24: - | AK24: No | AL24: - | AM24: No | AN24: - | AO24: Yes | AP24: Charges dismissed | AQ24: 6 Ni 24/17 (EP) | AR24: 02.10.2019 | AS24: 17.06.2019 | AT24: http://juris.bundespatentgericht.de/cgi-bin/rechtsprechung/document.py?Gericht=bpatg&Art=en&sid=9be8db4304df34a7cf8fe900676cd57d&nr=37403&pos=0&anz=1&Blank=1.pdf | AU24: EP99965566(A), EP1062744(B1) | AV24: DE69933654T2, DE69934577T2, DE69935715T2
A25: 2 O 136/18 | B25: Mannheim | C25: Yes!* | D25: Yes | E25: No | F25: Yes | G25: https://www.katheraugenstein.com:443/app/uploads/2020-08-21-LG-Mannheim-2-O-136_18-DE.pdf | H25: https://www.katheraugenstein.com:443/app/uploads/2020-08-21-LG-Mannheim-2-O-136_18-EN.pdf | I25: Yes | J25: No | K25: - | L25: - | M25: 01.03.2018 | N25: 21.08.2020 | Q25: - | S25: 15.12.2014 | U25: 17.10.2018 | V25: 17.10.2018 | W25: 01.02.2016 | X25: 21.08.2020 | Y25: Yes | Z25: Yes | AA25: Yes | AB25: Yes | AC25: No | AD25: No | AE25: No | AF25: ? | AG25: Yes | AH25: Yes | AI25: Yes | AJ25: Reversed | AK25: No | AL25: - | AM25: No | AN25: - | AO25: Yes | AP25: Partially invalid for Germany | AQ25: 2 Ni 14/17 (EP) | AR25: 19.09.2019 | AS25: 10.03.2017? | AT25: http://juris.bundespatentgericht.de/cgi-bin/rechtsprechung/document.py?Gericht=bpatg&Art=en&sid=bbc8084d4a1b275b62cfa1c3e7203c48&nr=39474&pos=0&anz=1&Blank=1.pdf | AU25: EP09741793(A), EP2294737 | AV25: -
A26: 2 O 131/19 | B26: Mannheim | C26: Yes* | D26: Yes | E26: Yes | F26: Yes | G26: https://www.katheraugenstein.com:443/app/uploads/2021-03-02-LG-Mannheim-2-O-131-19-DE.pdf | H26: https://www.katheraugenstein.com:443/app/uploads/2021-03-02-LG-Mannheim-2-O-131-19-EN.pdf | I26: Yes | J26: No | K26: - | L26: - | M26: 15.11.2019 | N26: 02.03.2021 | Q26: - | S26: 29.03.2016 | W26: ? | X26: 02.03.2021 | Y26: Yes | Z26: No | AA26: Yes | AB26: No | AC26: Yes | AD26: Yes | AE26: Yes | AF26: ? | AG26: ? | AH26: No | AI26: No | AJ26: - | AK26: No | AL26: - | AM26: No | AN26: - | AO26: ? | AP26: ? | AQ26: ? | AR26: ? | AS26: ? | AT26: ? | AU26: ? | AV26: ?
A27: 2 O 34/19 | B27: Mannheim | C27: Yes! | D27: Yes | E27: Yes | F27: Yes | G27: https://www.katheraugenstein.com:443/app/uploads/2020-08-18-LG-Mannheim-2-O-34_19-DE.pdf | H27: https://www.katheraugenstein.com:443/app/uploads/2020-08-18-LG-Mannheim-2-O-34_19-EN.pdf | I27: Yes | J27: No | K27: - | L27: - | M27: 01.04.2019 | N27: 18.08.2020 | Q27: - | S27: 21.06.2016 | U27: 21.03.2019 | V27: 21.03.2019 | W27: 09.11.2016 | X27: 18.08.2020 | Y27: - | Z27: No | AA27: Yes | AB27: No | AC27: - | AD27: - | AE27: - | AF27: Yes | AG27: Yes | AH27: Yes | AI27: Yes | AJ27: Upheld? | AK27: No | AL27: - | AM27: No | AN27: - | AO27: Yes | AP27: - | AQ27: 5 Ni 24/19 (EP) | AR27: - | AS27: 04.12.2019 | AT27: - | AU27: EP15181110(A), EP2981103(B1) | AV27: -
A28: 7 O 15350/19 | B28: Munich | C28: Yes | D28: Yes | E28: Yes | F28: No | G28: - | H28: - | J28: Yes | K28: https://www.gesetze-bayern.de/Content/Document/Y-300-Z-GRURRS-B-2021-N-23157 | L28: - | M28: 19.02.2021 | N28: 19.08.2021 | Q28: - | S28: 21.08.2019 | U28: 10.10.2019 | V28: 10.10.2019 | W28: 21.08.2019 | X28: 19.08.2021 | Y28: Yes | Z28: No | AA28: Yes | AB28: No | AC28: - | AD28: - | AE28: - | AF28: ? | AG28: ? | AH28: No | AI28: No | AJ28: - | AK28: No | AL28: - | AM28: No | AN28: - | AO28: Yes | AP28: Invalid for Germany | AQ28: 4 Ni 11/21 (EP) | AR28: 02.08.2022 | AS28: 10.09.2020 | AT28: http://juris.bundespatentgericht.de/cgi-bin/rechtsprechung/document.py?Gericht=bpatg&Art=en&sid=94908c89b72e65e1f7d29010c2144ab1&nr=43267&pos=0&anz=1&Blank=1.pdf | AU28: EP14889618(A), EP3132443 | AV28: -
A29: 2 O 75/21 | B29: Mannheim | C29: Yes* | D29: Yes | E29: Yes | F29: Yes | G29: https://www.katheraugenstein.com/app/uploads/2022-07-05-LG-Mannheim-2-O-75_21-LTE-Mobilfunkstandard.pdf | H29: https://www.katheraugenstein.com/app/uploads/2022-07-05-Regional-Court-Mannheim-2-O-75_21-LTE-Mobilfunkstandard-EN.pdf | I29: Yes | J29: No | K29: - | L29: - | M29: 08.07.2021 | N29: 05.07.2022 | Q29: - | S29: ? | U29: 08.07.2021 | V29: 08.07.2021 | W29: ? | X29: 05.07.2022 | Y29: Yes | Z29: No | AA29: Yes | AB29: No | AC29: - | AD29: - | AE29: - | AF29: ? | AG29: ? | AH29: Yes | AI29: Yes | AJ29: Rejected the application for temporarily stop | AK29: No | AL29: - | AM29: No | AN29: - | AO29: Yes | AP29: - | AQ29: 5 Ni 60/21 (EP) | AR29: - | AS29: 06.12.2021 | AT29: - | AU29: EP15181110(A), EP2981103, EP17163537(A), EP3220562 | AV29: -
A30: 7 O 28/16 | B30: Mannheim | C30: Yes! | D30: Yes | E30: No | F30: Yes | G30: https://www.katheraugenstein.com/app/uploads/2017-11-10-7-O-28_16-DE-pdf-1.pdf | H30: https://www.katheraugenstein.com/app/uploads/2017-11-10-7-O-28_16-EN-pdf-1.pdf | I30: Yes | J30: No | K30: - | L30: - | M30: 03.02.2016 | N30: 10.11.2017 | Q30: - | S30: 01.11.2013 | U30: 03.02.2016 | V30: 03.02.2016 | W30: 01.11.2013 | X30: 10.11.2017 | Y30: Yes | Z30: Yes | AA30: Yes | AB30: Yes | AC30: No | AD30: No | AE30: - | AF30: ? | AG30: ? | AH30: No | AI30: No | AJ30: - | AK30: No | AL30: - | AM30: No | AN30: - | AO30: Yes | AP30: Invalid for Germany | AQ30: 6 Ni 50/16 (EP) | AR30: 09.01.2020 | AS30: 04.05.2016 | AT30: http://juris.bundespatentgericht.de/cgi-bin/rechtsprechung/document.py?Gericht=bpatg&Art=en&sid=3652ff2c1f99b1fe95e3eef59630f1fa&nr=38914&pos=0&anz=1&Blank=1.pdf | AU30: EP04728378(A), EP1623511(B1) | AV30: DE602004005179T2
A31: 2 O 106/14 | B31: Mannheim | C31: Yes | D31: Yes | E31: Yes | F31: Yes | G31: https://www.katheraugenstein.com/app/uploads/2015-11-27-2-O-106_-14-DE-pdf.pdf | H31: https://www.katheraugenstein.com/app/uploads/2015-11-27-2-O-106_14-EN-pdf-1.pdf | I31: Yes | J31: Yes | K31: http://lrbw.juris.de/cgi-bin/laender_rechtsprechung/document.py?Gericht=bw&GerichtAuswahl=Landgerichte&Art=en&sid=f3caef45b2432c5f65740b9bb5cc38da&nr=20078&anz=1&pos=0&Blank=1 | L31: - | M31: 15.06.2014 | N31: 27.11.2015 | O31: 1 | Q31: - | S31: 01.07.2014 | U31: 15.06.2014 | V31: 15.06.2014 | W31: 25.03.2015 | X31: 27.11.2015 | Y31: Yes | Z31: No | AA31: Yes | AB31: No | AC31: Yes | AD31: Yes | AE31: - | AF31: ? | AG31: Yes | AH31: Yes | AI31: Yes | AJ31: ? | AK31: No | AL31: - | AM31: No | AN31: - | AO31: Yes | AP31: - | AQ31: 4 Ni 6/15 (EP), 6 Ni 7/16 (EP), 6 Ni 63/16 (EP), 4 Ni 33/14 (EP) | AR31: - | AS31: 06.11.2014 | AT31: - | AU31: EP99952183(A), EP1125284 | AV31: DE69910240T2, DE69913724T2
A32: 21 O 11522/21 | B32: Munich | C32: Yes | D32: Yes | E32: Yes | F32: Yes | G32: https://www.katheraugenstein.com/app/uploads/LG-Muenchen-I-05.08.2022-21-O-11522_21-Pitch-Lag-Schaetzung.pdf | H32: https://www.katheraugenstein.com/app/uploads/LG-Muenchen-I-05.08.2022-21-O-11522_21-Pitch-Lag-Schaetzung-EN.pdf | I32: Yes | J32: Yes | K32: https://www.gesetze-bayern.de/Content/Document/Y-300-Z-GRURRS-B-2022-N-26267?hl=true | L32: 21 O 8879/21; 21 O 8890/21 | M32: 23.03.2022 | N32: 05.08.2022 | Q32: - | S32: ? | W32: ? | X32: 05.08.2022 | Y32: Yes | Z32: No | AA32: Yes | AB32: No | AC32: - | AD32: - | AE32: - | AF32: ? | AG32: Yes | AH32: No | AI32: No | AJ32: - | AK32: No | AL32: - | AM32: No | AN32: - | AO32: Yes | AP32: - | AQ32: 4 Ni 33/22 (EP) | AR32: - | AS32: 19.04.2022 | AT32: - | AU32: EP07826610(A), EP2080193 | AV32: -
A33: 21 O 1910/22 | B33: Munich | C33: Yes | D33: Yes | E33: Yes | F33: Yes | G33: https://www.katheraugenstein.com/app/uploads/2023-04-19-LG-Muenchen-I-21-O-1910_22-Rahmenloeschung.pdf | H33: https://www.katheraugenstein.com/app/uploads/2023-04-19-Regional-Court-Munich-I-21-O-1910_22-Rahmenloeschung_en.pdf | I33: Yes | J33: Yes | K33: https://www.gesetze-bayern.de/Content/Document/Y-300-Z-GRURRS-B-2023-N-18036?hl=true | L33: - | M33: 18.01.2023 | N33: 19.04.2023 | Q33: - | S33: ? | W33: ? | X33: 19.04.2023 | Y33: Yes | Z33: No | AA33: Yes | AB33: No | AC33: - | AD33: - | AE33: - | AF33: ? | AG33: ? | AH33: No | AI33: No | AJ33: - | AK33: No | AL33: - | AM33: No | AN33: - | AO33: Yes | AP33: Charges dismissed | AQ33: 4 Ni 9/21 (EP) | AR33: 06.12.2021 | AS33: 08.05.2020 | AT33: http://juris.bundespatentgericht.de/cgi-bin/rechtsprechung/document.py?Gericht=bpatg&Art=en&sid=c6c57cea8d597be4ddff88df5e0c1bd4&nr=42398&pos=0&anz=1&Blank=1.pdf | AU33: EP03727094(A), EP1509903 | AV33: -
A34: 21 O 4140/21 | B34: Munich | C34: Yes | D34: Yes | E34: Yes | F34: Yes | G34: https://www.katheraugenstein.com/app/uploads/2023-02-17-LG-Muenchen-21-O-4140_21.pdf | H34: https://www.katheraugenstein.com/app/uploads/2023-02-17-Regional-Court-Munich-21-O-4140_21.pdf | I34: Yes | J34: Yes | K34: https://www.gesetze-bayern.de/Content/Document/Y-300-Z-GRURRS-B-2023-N-11247?hl=true | L34: - | M34: 21.09.2022 | N34: 17.02.2023 | Q34: - | S34: 01.03.2021 | W34: 01.03.2021 | X34: 17.02.2023 | Y34: Yes | Z34: No | AA34: Yes | AB34: No | AC34: - | AD34: - | AE34: - | AF34: Yes | AG34: ? | AH34: No | AI34: No | AJ34: - | AK34: No | AL34: - | AM34: No | AN34: - | AO34: Yes | AP34: Partially invalid for Germany | AQ34: 2 Ni 7/21 (EP) | AR34: 27.01.2023 | AS34: 08.04.2019 | AT34: http://juris.bundespatentgericht.de/cgi-bin/rechtsprechung/document.py?Gericht=bpatg&Art=en&sid=ffd14ec36a6dfbd64662b605345661a0&nr=43641&pos=0&anz=1&Blank=1.pdf | AU34: EP11714644(A), EP2559245 | AV34: -
A35: 7 O 8818/19 | B35: Munich | C35: Yes | D35: Yes | E35: Yes | F35: Yes | G35: https://www.katheraugenstein.com/app/uploads/2020-09-10-LG-Muenchen-7-O-8818_19-DE.pdf | H35: https://www.katheraugenstein.com/app/uploads/2020-09-10-LG-Muenchen-7-O-8818_19-EN.pdf | I35: Yes | J35: Yes | K35: https://www.gesetze-bayern.de/Content/Document/Y-300-Z-GRURRS-B-2020-N-22577?hl=true | L35: - | M35: 28.06.2019 | N35: 10.09.2020 | Q35: - | S35: 2016 | U35: 28.06.2019 | V35: 28.06.2019 | W35: 08.09.2016 | X35: 10.09.2020 | Y35: Yes | Z35: No | AA35: Yes | AB35: No | AC35: Yes | AD35: Yes | AE35: Yes | AF35: Yes | AG35: Yes | AH35: No | AI35: No | AJ35: - | AK35: No | AL35: - | AM35: No | AN35: - | AO35: Yes | AP35: - | AQ35: 6 Ni 2/20 (EP), 8 Ni 12/23 (EP), 4 Ni 7/22 (EP) | AR35: - | AS35: 10.02.2020, 09.02.2020 | AT35: - | AU35: EP13003937(A), EP2667676(B1) | AV35: -
A36: 4a O 27/16 | B36: Duesseldorf | C36: Yes | D36: Yes | E36: No | F36: Yes | G36: https://www.justiz.nrw.de/nrwe/lgs/duesseldorf/lg_duesseldorf/j2017/4a_O_27_16_Urteil_20170713.html | H36: - | I36: Yes | J36: Yes | K36: https://www.justiz.nrw.de/nrwe/lgs/duesseldorf/lg_duesseldorf/j2017/4a_O_27_16_Urteil_20170713.html | L36: - | M36: 18.03.2016 | N36: 13.07.2017 | Q36: 1000000/250000 | S36: 04.12.2012 | U36: 18.03.2016 | V36: 18.03.2016 | W36: 04.12.2012 | X36: 13.07.2017 | Y36: Yes | Z36: Yes | AA36: Yes | AB36: Yes | AC36: No | AD36: No | AE36: - | AF36: ? | AG36: Yes | AH36: No | AI36: No | AJ36: - | AK36: No | AL36: - | AM36: No | AN36: - | AO36: Yes | AP36: Partially invalid for Germany | AQ36: 6 Ni 10/15 (EP) | AR36: 06.10.2017 | AS36: 13.03.2015 | AT36: http://juris.bundespatentgericht.de/cgi-bin/rechtsprechung/document.py?Gericht=bpatg&Art=en&sid=1740b61095c41bc7591b0735ca03401a&nr=36064&pos=0&anz=1&Blank=1.pdf | AU36: EP96931826(A), EP0852885 | AV36: DE69635453C5, DE69635453T2
A37: 4a O 154/15 | B37: Duesseldorf | C37: Yes | D37: Yes | E37: No | F37: Yes | G37: https://www.justiz.nrw.de/nrwe/lgs/duesseldorf/lg_duesseldorf/j2017/4a_O_154_15_Urteil_20170713.html | H37: - | I37: Yes | J37: Yes | K37: https://www.justiz.nrw.de/nrwe/lgs/duesseldorf/lg_duesseldorf/j2017/4a_O_154_15_Urteil_20170713.html | L37: - | M37: 11.06.2015 | N37: 13.07.2017 | O37: 1 | Q37: 1000000/250000 | S37: 04.12.2012 | U37: 06.11.2015 | V37: 06.11.2015 | W37: 04.12.2012 | X37: 13.07.2017 | Y37: Yes | Z37: Yes | AA37: Yes | AB37: Yes | AC37: No | AD37: No | AE37: - | AF37: ? | AG37: Yes | AH37: No | AI37: No | AJ37: - | AK37: No | AL37: - | AM37: No | AN37: - | AO37: Yes | AP37: Partially invalid for Germany | AQ37: 6 Ni 10/15 (EP) | AR37: 06.10.2017 | AS37: 13.03.2015 | AT37: http://juris.bundespatentgericht.de/cgi-bin/rechtsprechung/document.py?Gericht=bpatg&Art=en&sid=1740b61095c41bc7591b0735ca03401a&nr=36064&pos=0&anz=1&Blank=1.pdf | AU37: EP96931826(A), EP0852885 | AV37: DE69635453C5, DE69635453T3
A38: 14d O 13/17 | B38: Duesseldorf | C38: Yes | D38: Yes | E38: No | F38: Yes | G38: https://www.justiz.nrw.de/nrwe/lgs/duesseldorf/lg_duesseldorf/j2017/14d_O_13_17_Urteil_20171109.html | H38: - | I38: Yes | J38: Yes | K38: https://www.justiz.nrw.de/nrwe/lgs/duesseldorf/lg_duesseldorf/j2017/14d_O_13_17_Urteil_20171109.html | L38: - | M38: 07.09.2017 | N38: 09.11.2017 | Q38: ? | S38: ? | U38: 07.09.2015 | W38: ? | X38: 09.11.2017 | Y38: Yes | Z38: Yes | AA38: ? | AB38: ? | AC38: No | AD38: ? | AE38: ? | AF38: ? | AG38: ? | AH38: No | AI38: No | AJ38: - | AK38: No | AL38: - | AM38: No | AN38: - | AO38: ? | AP38: ? | AQ38: ? | AR38: ? | AS38: ? | AT38: ? | AU38: ? | AV38: ?
A39: 7 O 38/14 | B39: Mannheim | C39: Yes! | D39: Yes? | E39: No | F39: No | G39: - | H39: - | I39: Yes | J39: No | K39: - | L39: - | M39: 21.03.2014 | N39: 26.02.2016 | O39: 1 | Q39: - | S39: ? | U39: 21.03.2014 | V39: 21.03.2014 | W39: ? | X39: 26.02.2016 | Y39: - | Z39: ? | AA39: - | AB39: - | AC39: - | AD39: - | AE39: - | AF39: ? | AG39: ? | AH39: No | AI39: No | AJ39: - | AK39: No | AL39: - | AM39: No | AN39: - | AO39: Yes | AP39: Fully revoked | AQ39: 19 W (pat) 69/13 | AR39: 12.04.2016 | AS39: 21.11.2013 | AT39: http://juris.bundespatentgericht.de/cgi-bin/rechtsprechung/document.py?Gericht=bpatg&Art=en&sid=aff07b20593ede41bbe8007fa65d4a0d&nr=28089&pos=1&anz=2&Blank=1.pdf | AU39: DE19910239(A), DE19910239 | AV39: DE19910239A1, DE19910239B4, DE20024006U1, DE20024007U1
A40: 7 O 24/14 | B40: Mannheim | C40: Yes! | D40: Yes | E40: Yes | F40: No | G40: - | H40: - | I40: Yes | J40: No | K40: - | L40: - | M40: 26.02.2014 | N40: 21.11.2014/04.03.2016 | O40: 1 | Q40: - | S40: ? | U40: 26.02.2014 | V40: 26.02.2014 | W40: 13.03.2015 | X40: 21.11.2014/04.03.2016 | Y40: - | Z40: No | AA40: Yes | AB40: Yes | AC40: Yes | AD40: Yes | AE40: Yes | AF40: Yes | AG40: Yes | AH40: Yes | AI40: Yes | AJ40: ? | AK40: No | AL40: - | AM40: No | AN40: - | AO40: Yes | AP40: Invalid for Germany | AQ40: 2 Ni 5/16 (EP) | AR40: 02.02.2017 | AS40: 23.07.2014 | AT40: http://juris.bundespatentgericht.de/cgi-bin/rechtsprechung/document.py?Gericht=bpatg&Art=en&sid=591686bf13eeae126c67a6bd158e28d8&nr=29077&pos=0&anz=1&Blank=1.pdf | AU40: EP96301947(A), EP0734181(B1) | AV40: DE69628487T2
...

Sheet Old graphs
